<sdf version='1.7'>
  <model name='two_wheel_mr'>
    <link name='base_footprint'>
      <inertial>
        <pose>0.00117 -3e-06 0.157701 0 -0 0</pose>
        <mass>78.6431</mass>
        <inertia>
          <ixx>2.53327</ixx>
          <ixy>0.0171572</ixy>
          <ixz>-0.0045641</ixz>
          <iyy>4.27984</iyy>
          <iyz>5.63912e-06</iyz>
          <izz>6.35902</izz>
        </inertia>
      </inertial>
      <collision name='base_footprint_fixed_joint_lump__base_link_collision'>
        <pose>0 0 0 0 -0 0</pose>
        <geometry>
          <mesh>
            <scale>1 1 1</scale>
            <uri>model://two_wheel_mr_gazebo/meshes/base.STL</uri>
          </mesh>
        </geometry>
      </collision>
      <collision name='base_footprint_fixed_joint_lump__caster1_wheel_link_collision_1'>
        <pose>0.31938 0.18313 0.0747 1.5708 -0 1.5708</pose>
        <geometry>
          <mesh>
            <scale>1 1 1</scale>
            <uri>model://two_wheel_mr_gazebo/meshes/lbphu1.STL</uri>
          </mesh>
        </geometry>
      </collision>
      <collision name='base_footprint_fixed_joint_lump__caster1_link_collision_2'>
        <pose>0.321189 0.158135 0.025005 1.5708 3e-06 0.57162</pose>
        <geometry>
          <mesh>
            <scale>1 1 1</scale>
            <uri>model://two_wheel_mr_gazebo/meshes/lphu1.STL</uri>
          </mesh>
        </geometry>
      </collision>
      <collision name='base_footprint_fixed_joint_lump__caster2_wheel_link_collision_3'>
        <pose>0.31938 -0.18288 0.0897 -1.5708 -0 -0.57871</pose>
        <geometry>
          <mesh>
            <scale>1 1 1</scale>
            <uri>model://two_wheel_mr_gazebo/meshes/lbphu2.STL</uri>
          </mesh>
        </geometry>
      </collision>
      <collision name='base_footprint_fixed_joint_lump__caster2_link_collision_4'>
        <pose>0.344361 -0.184867 0.025005 -1.5708 4e-06 0.99209</pose>
        <geometry>
          <mesh>
            <scale>1 1 1</scale>
            <uri>model://two_wheel_mr_gazebo/meshes/lphu2.STL</uri>
          </mesh>
        </geometry>
      </collision>
      <collision name='base_footprint_fixed_joint_lump__caster3_wheel_link_collision_5'>
        <pose>-0.31863 0.18313 0.0897 -1.5708 0 -3.14159</pose>
        <geometry>
          <mesh>
            <scale>1 1 1</scale>
            <uri>model://two_wheel_mr_gazebo/meshes/lbphu3.STL</uri>
          </mesh>
        </geometry>
      </collision>
      <collision name='base_footprint_fixed_joint_lump__caster3_link_collision_6'>
        <pose>-0.34063 0.19513 0.025005 0.391804 4e-06 -1.57079</pose>
        <geometry>
          <mesh>
            <scale>1 1 1</scale>
            <uri>model://two_wheel_mr_gazebo/meshes/lphu3.STL</uri>
          </mesh>
        </geometry>
      </collision>
      <collision name='base_footprint_fixed_joint_lump__caster4_wheel_link_collision_7'>
        <pose>-0.31863 -0.18288 0.0747 1.5708 -0 1.5708</pose>
        <geometry>
          <mesh>
            <scale>1 1 1</scale>
            <uri>model://two_wheel_mr_gazebo/meshes/lbphu4.STL</uri>
          </mesh>
        </geometry>
      </collision>
      <collision name='base_footprint_fixed_joint_lump__caster4_link_collision_8'>
        <pose>-0.296777 -0.170615 0.025005 -3.14159 -0 1.5829</pose>
        <geometry>
          <mesh>
            <scale>1 1 1</scale>
            <uri>model://two_wheel_mr_gazebo/meshes/lphu4.STL</uri>
          </mesh>
        </geometry>
      </collision>
      <collision name='base_footprint_fixed_joint_lump__base_scan_collision_9'>
        <pose>0 0 0.255 1.5707 -0 -1.57319</pose>
        <geometry>
          <mesh>
            <scale>0.001 0.001 0.001</scale>
            <uri>model://two_wheel_mr_gazebo/meshes/rplidar.dae</uri>
          </mesh>
        </geometry>
        <surface>
          <contact>
            <ode/>
          </contact>
          <friction>
            <ode/>
          </friction>
        </surface>
      </collision>
      <visual name='base_footprint_fixed_joint_lump__base_link_visual'>
        <pose>0 0 0 0 -0 0</pose>
        <geometry>
          <mesh>
            <scale>1 1 1</scale>
            <uri>model://two_wheel_mr_gazebo/meshes/base.STL</uri>
          </mesh>
        </geometry>
      </visual>
      <visual name='base_footprint_fixed_joint_lump__caster1_wheel_link_visual_1'>
        <pose>0.31938 0.18313 0.0747 1.5708 -0 1.5708</pose>
        <geometry>
          <mesh>
            <scale>1 1 1</scale>
            <uri>model://two_wheel_mr_gazebo/meshes/lbphu1.STL</uri>
          </mesh>
        </geometry>
      </visual>
      <visual name='base_footprint_fixed_joint_lump__caster1_link_visual_2'>
        <pose>0.321189 0.158135 0.025005 1.5708 3e-06 0.57162</pose>
        <geometry>
          <mesh>
            <scale>1 1 1</scale>
            <uri>model://two_wheel_mr_gazebo/meshes/lphu1.STL</uri>
          </mesh>
        </geometry>
      </visual>
      <visual name='base_footprint_fixed_joint_lump__caster2_wheel_link_visual_3'>
        <pose>0.31938 -0.18288 0.0897 -1.5708 -0 -0.57871</pose>
        <geometry>
          <mesh>
            <scale>1 1 1</scale>
            <uri>model://two_wheel_mr_gazebo/meshes/lbphu2.STL</uri>
          </mesh>
        </geometry>
      </visual>
      <visual name='base_footprint_fixed_joint_lump__caster2_link_visual_4'>
        <pose>0.344361 -0.184867 0.025005 -1.5708 4e-06 0.99209</pose>
        <geometry>
          <mesh>
            <scale>1 1 1</scale>
            <uri>model://two_wheel_mr_gazebo/meshes/lphu2.STL</uri>
          </mesh>
        </geometry>
      </visual>
      <visual name='base_footprint_fixed_joint_lump__caster3_wheel_link_visual_5'>
        <pose>-0.31863 0.18313 0.0897 -1.5708 0 -3.14159</pose>
        <geometry>
          <mesh>
            <scale>1 1 1</scale>
            <uri>model://two_wheel_mr_gazebo/meshes/lbphu3.STL</uri>
          </mesh>
        </geometry>
      </visual>
      <visual name='base_footprint_fixed_joint_lump__caster3_link_visual_6'>
        <pose>-0.34063 0.19513 0.025005 0.391804 4e-06 -1.57079</pose>
        <geometry>
          <mesh>
            <scale>1 1 1</scale>
            <uri>model://two_wheel_mr_gazebo/meshes/lphu3.STL</uri>
          </mesh>
        </geometry>
      </visual>
      <visual name='base_footprint_fixed_joint_lump__caster4_wheel_link_visual_7'>
        <pose>-0.31863 -0.18288 0.0747 1.5708 -0 1.5708</pose>
        <geometry>
          <mesh>
            <scale>1 1 1</scale>
            <uri>model://two_wheel_mr_gazebo/meshes/lbphu4.STL</uri>
          </mesh>
        </geometry>
      </visual>
      <visual name='base_footprint_fixed_joint_lump__caster4_link_visual_8'>
        <pose>-0.296777 -0.170615 0.025005 -3.14159 -0 1.5829</pose>
        <geometry>
          <mesh>
            <scale>1 1 1</scale>
            <uri>model://two_wheel_mr_gazebo/meshes/lphu4.STL</uri>
          </mesh>
        </geometry>
      </visual>
      <visual name='base_footprint_fixed_joint_lump__base_scan_visual_9'>
        <pose>0 0 0.255 1.5707 -0 -1.57319</pose>
        <geometry>
          <mesh>
            <scale>0.001 0.001 0.001</scale>
            <uri>model://two_wheel_mr_gazebo/meshes/rplidar.dae</uri>
          </mesh>
        </geometry>
        <material>
          <script>
            <name>Gazebo/Black</name>
            <uri>file://media/materials/scripts/gazebo.material</uri>
          </script>
        </material>
      </visual>
      <gravity>1</gravity>
      <sensor name='rplidar' type='ray'>
        <visualize>1</visualize>
        <update_rate>40</update_rate>
        <ray>
          <scan>
            <horizontal>
              <samples>360</samples>
              <resolution>1</resolution>
              <min_angle>-3.1415</min_angle>
              <max_angle>3.1415</max_angle>
            </horizontal>
          </scan>
          <range>
            <min>0.1</min>
            <max>7</max>
            <resolution>0.001</resolution>
          </range>
        </ray>
        <plugin name='gazebo_ros_head_rplidar_controller' filename='libgazebo_ros_ray_sensor.so'>
          <ros>
            <remapping>~/out:=scan</remapping>
          </ros>
          <output_type>sensor_msgs/LaserScan</output_type>
          <frame_name>base_scan</frame_name>
        </plugin>
        <pose>0 0 0.255 0 -0 0</pose>
      </sensor>
    </link>
    <joint name='left_wheel_joint' type='revolute'>
      <pose relative_to='base_footprint'>0 0.21908 0.062877 1.5708 0.003081 1.5708</pose>
      <parent>base_footprint</parent>
      <child>left_wheel_link</child>
      <axis>
        <xyz>1 0 0</xyz>
        <limit>
          <lower>-1e+16</lower>
          <upper>1e+16</upper>
        </limit>
        <dynamics>
          <spring_reference>0</spring_reference>
          <spring_stiffness>0</spring_stiffness>
        </dynamics>
      </axis>
    </joint>
    <link name='left_wheel_link'>
      <pose relative_to='left_wheel_joint'>0 0 0 0 -0 0</pose>
      <inertial>
        <pose>1e-06 6e-06 9e-06 0 -0 0</pose>
        <mass>0.3265</mass>
        <inertia>
          <ixx>0.00067921</ixx>
          <ixy>2.1629e-18</ixy>
          <ixz>1.2457e-17</ixz>
          <iyy>0.00038694</iyy>
          <iyz>3.8673e-10</iyz>
          <izz>0.00038694</izz>
        </inertia>
      </inertial>
      <collision name='left_wheel_link_collision'>
        <pose>0 0 0 0 -0 0</pose>
        <geometry>
          <mesh>
            <scale>1 1 1</scale>
            <uri>model://two_wheel_mr_gazebo/meshes/lchinh1.STL</uri>
          </mesh>
        </geometry>
        <surface>
          <contact>
            <ode>
              <kp>1e+07</kp>
              <kd>1</kd>
            </ode>
          </contact>
          <friction>
            <ode>
              <mu>1</mu>
              <mu2>1</mu2>
              <fdir1>1 0 0</fdir1>
            </ode>
          </friction>
        </surface>
      </collision>
      <visual name='left_wheel_link_visual'>
        <pose>0 0 0 0 -0 0</pose>
        <geometry>
          <mesh>
            <scale>1 1 1</scale>
            <uri>model://two_wheel_mr_gazebo/meshes/lchinh1.STL</uri>
          </mesh>
        </geometry>
      </visual>
    </link>
    <joint name='right_wheel_joint' type='revolute'>
      <pose relative_to='base_footprint'>0 -0.21908 0.062877 2.0284 -0.003081 1.5708</pose>
      <parent>base_footprint</parent>
      <child>right_wheel_link</child>
      <axis>
        <xyz>0.99998 -0.005527 0.002722</xyz>
        <limit>
          <lower>-1e+16</lower>
          <upper>1e+16</upper>
        </limit>
        <dynamics>
          <spring_reference>0</spring_reference>
          <spring_stiffness>0</spring_stiffness>
        </dynamics>
      </axis>
    </joint>
    <link name='right_wheel_link'>
      <pose relative_to='right_wheel_joint'>0 0 0 0 -0 0</pose>
      <inertial>
        <pose>1e-06 4e-06 1e-05 0 -0 0</pose>
        <mass>0.3265</mass>
        <inertia>
          <ixx>0.00067921</ixx>
          <ixy>7.1118e-18</ixy>
          <ixz>9.5532e-18</ixz>
          <iyy>0.00038694</iyy>
          <iyz>2.7867e-10</iyz>
          <izz>0.00038694</izz>
        </inertia>
      </inertial>
      <collision name='right_wheel_link_collision'>
        <pose>0 0 0 0 -0 0</pose>
        <geometry>
          <mesh>
            <scale>1 1 1</scale>
            <uri>model://two_wheel_mr_gazebo/meshes/lchinh2.STL</uri>
          </mesh>
        </geometry>
        <surface>
          <contact>
            <ode>
              <kp>1e+07</kp>
              <kd>1</kd>
            </ode>
          </contact>
          <friction>
            <ode>
              <mu>1</mu>
              <mu2>1</mu2>
              <fdir1>1 0 0</fdir1>
            </ode>
          </friction>
        </surface>
      </collision>
      <visual name='right_wheel_link_visual'>
        <pose>0 0 0 0 -0 0</pose>
        <geometry>
          <mesh>
            <scale>1 1 1</scale>
            <uri>model://two_wheel_mr_gazebo/meshes/lchinh2.STL</uri>
          </mesh>
        </geometry>
      </visual>
    </link>
    <plugin name='gazebo_ros_control' filename='libgazebo_ros_control.so'>
      <robotSimType>gazebo_ros_control/DefaultRobotHWSim</robotSimType>
      <legacyModeNS>0</legacyModeNS>
    </plugin>
    <static>0</static>
    <plugin name='object_controller' filename='libgazebo_ros_planar_move.so'>
      <odometry_frame>odom</odometry_frame>
      <publish_rate>50.0</publish_rate>
      <update_rate>50.0</update_rate>
      <robot_base_frame>base_link</robot_base_frame>
      <publish_tf>true</publish_tf>
      <publish_odom_tf>true</publish_odom_tf>
    </plugin>
  </model>
</sdf>
